Workbook
Name ACC_: "ACCESORIO"
Name CAJA: Val!$D$1:$D$20
Name d: [1]CEL!$A$5:$A$8860
Name DEST: Val!$B$1:$B$5
Name destino: Val!$B$1:$B$8
Name EQ: Equipos!$A$4:$A$97
Name Exa_: "EXACTA"
Name GAS: Gastos!$A$2:$A$18
Name Gas_: "GASTO"
Name item: Val!$A$1:$A$28
Name Kit_: "KIT"
Name mov: Movimiento!$A$3:$A$99
Name Prep_: "PREPAGA"
Name Prop_: "PROPIO"
Name Rep_: "REPOSICION"
Name Tarjeta: "{""Visa"" ; ""Master""}"
Name TDC: Val!$E$1:$E$13
Name VACIO: Val!$G$1:$G$6
Name Var: Val!$C$1:$C$11
Name Var_: "VARIO"

Sheet CAJA
A1: =MIN(A4:A2493) -> 45200 | B1: =IF(B2="",TODAY(),B2) -> 45545 | C1: EFE | D1: {=SUM(IF($J$4:$J$2493=C1,IF($A$4:$A$2493>=A1,IF($A$4:$A$2493<=$B$1,$D$4:$D$2493-$E$4:$E$2493,0),0),0))+J1} -> 406971.84 | F1: CC | G1: =SUMIF($I$4:$I$2493,"CC",$D$4:$D$2493)-SUMIFS($D$4:$D$2493,$G$4:$G$2493,"VARIO",$H$4:$H$2493,"PAGOCC")+L1 -> 0 | I1: EFE | J1: 909448.89 | N1: =SUMIFS($D$4:$D$2493,$I$4:$I$2493,"MEN",$B$4:$B$2493,M1)-SUMIFS($D$4:$D$2493,$G$4:$G$2493,"VARIO",$H$4:$H$2493,"PAGOMEN",$B$4:$B$2493,M1) -> 0 | R1: 45226
A2: Otra | C2: CHE | D2: {=SUM(IF($K$4:$K$2493<>"",IF($J$4:$J$2493<>"EFE",IF($I$4:$I$2493="CAJA",IF($A$4:$A$2493>=A1,IF($A$4:$A$2493<=$B$1,$D$4:$D$2493-$E$4:$E$2493,0),0),0),0),0))+J2} -> 0 | F2: MEN | G2: =SUMIF($I$4:$I$2493,"MEN",$D$4:$D$2493)-SUMIFS($D$4:$D$2493,$G$4:$G$2493,"VARIO",$H$4:$H$2493,"PAGOMEN") -> 0 | I2: CHE | N2: =SUMIFS($D$4:$D$2493,$I$4:$I$2493,"MEN",$B$4:$B$2493,M2)-SUMIFS($D$4:$D$2493,$G$4:$G$2493,"VARIO",$H$4:$H$2493,"PAGOMEN",$B$4:$B$2493,M2) -> 0 | P2: Caja | Q2: =SUMIF(G:G,"ACCESORIO",D:D) -> 859136 | R2: =SUMIFS(D:D,G:G,"ACCESORIO",A:A,R1) -> 11400
A3: FECHA | B3: DETALLE | C3: FAC. | D3: INGRESO | E3: SALIDA | F3: Cant | G3: OPERACIÓN | H3: TIPO/MODELO | I3: DEST | J3: MODO | K3: Nº | L3: Movim. | M3: OBSERVACIONES | P3: CajaAcc | Q3: =SUM(CajaAcc!D:D) -> 859136 | R3: =SUMIF(CajaAcc!A:A,R1,CajaAcc!D:D) -> 11400
A4: 45200 | B4: Alvarez 3415605392 | D4: 200 | F4: 1 | G4: propio | H4: sim-car | I4: caja | J4: efe | L4: Enzo
A5: 45200 | B5: Virtual | D5: 900 | G5: orga | I5: caja | J5: efe | L5: 3rosario
A6: 45200 | B6: Consumidor final | D6: 60 | F6: 3 | G6: propio | H6: sim-1175 | I6: caja | J6: efe | L6: 3rosario
A7: 45200 | B7: Consumidor final | D7: 3550 | F7: 1 | G7: accesorio | I7: tdc | J7: visa | K7: 390 | L7: 3rosario | M7: Débito
A8: 45200 | B8: Consumidor final | D8: 5450 | G8: accesorio | I8: caja | J8: efe | L8: 3rosario
A9: 45201 | B9: Transfer | D9: 233700 | F9: 1 | G9: vario | H9: transfer | I9: caja | J9: efe | L9: D1175
A10: 45201 | B10: Consumidor final | D10: 3089 | G10: accesorio | I10: caja | J10: efe | L10: 3rosario
A11: 45201 | B11: Consumidor final | D11: 34500 | F11: 2 | G11: accesorio | I11: tdc | J11: visa | K11: 397 | L11: 3rosario | M11: $56191,21 6cta
A12: 45201 | B12: Consumidor final | D12: 2650 | F12: 1 | G12: accesorio | I12: tdc | J12: master | K12: 398 | L12: 3rosario | M12: $2716,25 1cta
A13: 45201 | B13: Mansilla 3417515533 | D13: 200 | F13: 1 | G13: propio | H13: sim-car | I13: caja | J13: efe | L13: Lucas
A14: 45201 | B14: Manzanelli 3413274072 | D14: 200 | F14: 1 | G14: propio | H14: sim-car | I14: caja | J14: efe | L14: Lucas
A15: 45201 | B15: Caballero 9799906104 | F15: 1 | G15: p5g | H15: sim-car | L15: Lucas
A16: 45201 | B16: Consumidor final | D16: 3150 | F16: 1 | G16: accesorio | I16: tdc | J16: visa | K16: 399 | L16: 3rosario | M16: $3228,75 1cta
A17: 45201 | B17: Barbich 3462650900 | D17: 200 | F17: 1 | G17: propio | H17: sim-car | I17: caja | J17: efe | L17: Lucila
A18: 45201 | B18: Celis 3413486024 | D18: 200 | F18: 1 | G18: propio | H18: sim-car | I18: caja | J18: efe | L18: Lucila
A19: 45201 | B19: Transfer sim | C19: 0274 | F19: 3 | G19: propio | H19: sim-car | L19: 5corrientes
A20: 45201 | B20: Acc Demo Baf 3413257609 | E20: 1801 | F20: 1 | G20: gasto | H20: varios | I20: caja | J20: efe | L20: BAF
A21: 45201 | B21: Consumidor final | D21: 6100 | F21: 1 | G21: accesorio | I21: tdc | J21: visa | K21: 402 | L21: 3rosario | M21: $6252,25 1 cta
A22: 45201 | B22: Ybarra 3413481447 | D22: 200 | F22: 1 | G22: propio | H22: sim-car | I22: caja | J22: efe | L22: Lucila
A23: 45201 | B23: Ramirez 3415667065 | D23: 200 | F23: 1 | G23: propio | H23: sim-car | I23: caja | J23: efe | L23: Lucila
A24: 45201 | B24: Ramirez 3416889029 | D24: 200 | F24: 1 | G24: propio | H24: sim-car | I24: caja | J24: efe | L24: Lucila
A25: 45202 | B25: Filippi 3413499562 | F25: 1 | G25: cater | L25: Lucila | M25: tc-cti $129999,3
A26: 45202 | B26: Transfer | D26: 143200 | F26: 1 | G26: vario | H26: transfer | I26: caja | J26: efe | L26: D1175
A27: 45202 | B27: Cadete | E27: 800 | F27: 1 | G27: gasto | H27: flete | I27: caja | J27: efe | L27: BAF | M27: Folleteria
A28: 45202 | E28: 45400 | F28: 1 | G28: gasto | H28: sueldos | I28: caja | J28: efe | L28: CeibaUno
A29: 45202 | B29: Transfer sim | C29: 0275 | F29: 9 | G29: propio | H29: sim-car | L29: 5corrientes
A30: 45202 | B30: Consumidor final | D30: 14340 | G30: accesorio | I30: caja | J30: efe | L30: 3rosario
A31: 45202 | B31: Zarate 3413799783 | F31: 1 | G31: cater | L31: Enzo | M31: tc-cti $79999,31
A32: 45202 | B32: Consumidor final | D32: 2650 | F32: 1 | G32: accesorio | I32: tdc | J32: visa | K32: 413 | L32: 3rosario | M32: Débito
A33: 45202 | B33: Consumidor final | D33: 3350 | F33: 1 | G33: accesorio | I33: tdc | J33: visa | K33: 414 | L33: 3rosario | M33: Débito
A34: 45202 | B34: Consumidor final | D34: 3700 | F34: 1 | G34: accesorio | I34: tdc | J34: visa | K34: 418 | L34: 3rosario | M34: 1cta. $3792,50
A35: 45202 | B35: Cardozo 3416532396 | F35: 1 | G35: cater | L35: Enzo | M35: tc-cti $79999,31
A36: 45203 | B36: Transfer | D36: 169400 | F36: 1 | G36: vario | H36: transfer | I36: caja | J36: efe | L36: D1175
A37: 45203 | B37: Amadori, Enzo | E37: 147000 | F37: 1 | G37: gasto | H37: sueldos | I37: caja | J37: efe | L37: 3rosario
A38: 45203 | B38: Transfer sim | C38: 0276 | F38: 4 | G38: propio | H38: sim-car | L38: 5corrientes
A39: 45203 | B39: Consumidor final | D39: 7250 | G39: accesorio | I39: caja | J39: efe | L39: 3rosario
A40: 45203 | B40: Consumidor final | D40: 100 | F40: 5 | G40: propio | H40: sim-1175 | I40: caja | J40: efe | L40: 3rosario
...

Sheet CC
A1: Cliente | B1: Saldo | C1: Monto | D1: Cuota | E1: Cantidad | F1: Fecha | G1: Reclamar | H1: Pago | I1: Actual | J1: Situación | M1: Monto | N1: Cuotas | O1: MontoCuota
G2: =B2+D2*(IF(12*(+LEFT(MID(CELL("nombrearchivo",A1),FIND(".xlsx",CELL("nombrearchivo",A1))-4,4),2)-RIGHT(YEAR(F2),2))+RIGHT(MID(CELL("nombrearchivo",A1),FIND(".xlsx",CELL("nombrearchivo",A1))-4,4),2)-MONTH(F2)>E2,0,1)) -> 0 | H2: =SUMIFS(CAJA!D:D,CAJA!G:G,"VARIO",CAJA!H:H,"PAGO*",CAJA!B:B,A2) -> 0 | I2: =G2-H2 -> 0 | J2: =IF(I2>D2,"MOROSO",IF(I2>0,"COBRAR CUOTA","NORMAL")) -> NORMAL | M2: 500 | N2: 3 | O2: 180
G3: =B3+D3*(IF(12*(+LEFT(MID(CELL("nombrearchivo",A2),FIND(".xlsx",CELL("nombrearchivo",A2))-4,4),2)-RIGHT(YEAR(F3),2))+RIGHT(MID(CELL("nombrearchivo",A2),FIND(".xlsx",CELL("nombrearchivo",A2))-4,4),2)-MONTH(F3)>E3,0,1)) -> 0 | H3: =SUMIFS(CAJA!D:D,CAJA!G:G,"VARIO",CAJA!H:H,"PAGO*",CAJA!B:B,A3) -> 0 | I3: =G3-H3 -> 0 | J3: =IF(I3>D3,"MOROSO",IF(I3>0,"COBRAR CUOTA","NORMAL")) -> NORMAL | M3: 500 | N3: 6 | O3: 108
G4: =B4+D4*(IF(12*(+LEFT(MID(CELL("nombrearchivo",A3),FIND(".xlsx",CELL("nombrearchivo",A3))-4,4),2)-RIGHT(YEAR(F4),2))+RIGHT(MID(CELL("nombrearchivo",A3),FIND(".xlsx",CELL("nombrearchivo",A3))-4,4),2)-MONTH(F4)>E4,0,1)) -> 0 | H4: =SUMIFS(CAJA!D:D,CAJA!G:G,"VARIO",CAJA!H:H,"PAGO*",CAJA!B:B,A4) -> 0 | I4: =G4-H4 -> 0 | J4: =IF(I4>D4,"MOROSO",IF(I4>0,"COBRAR CUOTA","NORMAL")) -> NORMAL | M4: 1000 | N4: 3 | O4: 380
G5: =B5+D5*(IF(12*(+LEFT(MID(CELL("nombrearchivo",A4),FIND(".xlsx",CELL("nombrearchivo",A4))-4,4),2)-RIGHT(YEAR(F5),2))+RIGHT(MID(CELL("nombrearchivo",A4),FIND(".xlsx",CELL("nombrearchivo",A4))-4,4),2)-MONTH(F5)>E5,0,1)) -> 0 | H5: =SUMIFS(CAJA!D:D,CAJA!G:G,"VARIO",CAJA!H:H,"PAGO*",CAJA!B:B,A5) -> 0 | I5: =G5-H5 -> 0 | J5: =IF(I5>D5,"MOROSO",IF(I5>0,"COBRAR CUOTA","NORMAL")) -> NORMAL | M5: 1000 | N5: 6 | O5: 216
G6: =B6+D6*(IF(12*(+LEFT(MID(CELL("nombrearchivo",A5),FIND(".xlsx",CELL("nombrearchivo",A5))-4,4),2)-RIGHT(YEAR(F6),2))+RIGHT(MID(CELL("nombrearchivo",A5),FIND(".xlsx",CELL("nombrearchivo",A5))-4,4),2)-MONTH(F6)>E6,0,1)) -> 0 | H6: =SUMIFS(CAJA!D:D,CAJA!G:G,"VARIO",CAJA!H:H,"PAGO*",CAJA!B:B,A6) -> 0 | I6: =G6-H6 -> 0 | J6: =IF(I6>D6,"MOROSO",IF(I6>0,"COBRAR CUOTA","NORMAL")) -> NORMAL | M6: 1000 | N6: 10 | O6: 150
G7: =B7+D7*(IF(12*(+LEFT(MID(CELL("nombrearchivo",A6),FIND(".xlsx",CELL("nombrearchivo",A6))-4,4),2)-RIGHT(YEAR(F7),2))+RIGHT(MID(CELL("nombrearchivo",A6),FIND(".xlsx",CELL("nombrearchivo",A6))-4,4),2)-MONTH(F7)>E7,0,1)) -> 0 | H7: =SUMIFS(CAJA!D:D,CAJA!G:G,"VARIO",CAJA!H:H,"PAGO*",CAJA!B:B,A7) -> 0 | I7: =G7-H7 -> 0 | J7: =IF(I7>D7,"MOROSO",IF(I7>0,"COBRAR CUOTA","NORMAL")) -> NORMAL | M7: 5000 | N7: 3 | O7: 1900
G8: =B8+D8*(IF(12*(+LEFT(MID(CELL("nombrearchivo",A7),FIND(".xlsx",CELL("nombrearchivo",A7))-4,4),2)-RIGHT(YEAR(F8),2))+RIGHT(MID(CELL("nombrearchivo",A7),FIND(".xlsx",CELL("nombrearchivo",A7))-4,4),2)-MONTH(F8)>E8,0,1)) -> 0 | H8: =SUMIFS(CAJA!D:D,CAJA!G:G,"VARIO",CAJA!H:H,"PAGO*",CAJA!B:B,A8) -> 0 | I8: =G8-H8 -> 0 | J8: =IF(I8>D8,"MOROSO",IF(I8>0,"COBRAR CUOTA","NORMAL")) -> NORMAL | M8: 5000 | N8: 6 | O8: 1080
G9: =B9+D9*(IF(12*(+LEFT(MID(CELL("nombrearchivo",A8),FIND(".xlsx",CELL("nombrearchivo",A8))-4,4),2)-RIGHT(YEAR(F9),2))+RIGHT(MID(CELL("nombrearchivo",A8),FIND(".xlsx",CELL("nombrearchivo",A8))-4,4),2)-MONTH(F9)>E9,0,1)) -> 0 | H9: =SUMIFS(CAJA!D:D,CAJA!G:G,"VARIO",CAJA!H:H,"PAGO*",CAJA!B:B,A9) -> 0 | I9: =G9-H9 -> 0 | J9: =IF(I9>D9,"MOROSO",IF(I9>0,"COBRAR CUOTA","NORMAL")) -> NORMAL | M9: 5000 | N9: 10 | O9: 750
G10: =B10+D10*(IF(12*(+LEFT(MID(CELL("nombrearchivo",A9),FIND(".xlsx",CELL("nombrearchivo",A9))-4,4),2)-RIGHT(YEAR(F10),2))+RIGHT(MID(CELL("nombrearchivo",A9),FIND(".xlsx",CELL("nombrearchivo",A9))-4,4),2)-MONTH(F10)>E10,0,1)) -> 0 | H10: =SUMIFS(CAJA!D:D,CAJA!G:G,"VARIO",CAJA!H:H,"PAGO*",CAJA!B:B,A10) -> 0 | I10: =G10-H10 -> 0 | J10: =IF(I10>D10,"MOROSO",IF(I10>0,"COBRAR CUOTA","NORMAL")) -> NORMAL | M10: 5000 | N10: 12 | O10: 670
G11: =B11+D11*(IF(12*(+LEFT(MID(CELL("nombrearchivo",A10),FIND(".xlsx",CELL("nombrearchivo",A10))-4,4),2)-RIGHT(YEAR(F11),2))+RIGHT(MID(CELL("nombrearchivo",A10),FIND(".xlsx",CELL("nombrearchivo",A10))-4,4),2)-MONTH(F11)>E11,0,1)) -> 0 | H11: =SUMIFS(CAJA!D:D,CAJA!G:G,"VARIO",CAJA!H:H,"PAGO*",CAJA!B:B,A11) -> 0 | I11: =G11-H11 -> 0 | J11: =IF(I11>D11,"MOROSO",IF(I11>0,"COBRAR CUOTA","NORMAL")) -> NORMAL | M11: 5000 | N11: 18 | O11: 540
G12: =B12+D12*(IF(12*(+LEFT(MID(CELL("nombrearchivo",A11),FIND(".xlsx",CELL("nombrearchivo",A11))-4,4),2)-RIGHT(YEAR(F12),2))+RIGHT(MID(CELL("nombrearchivo",A11),FIND(".xlsx",CELL("nombrearchivo",A11))-4,4),2)-MONTH(F12)>E12,0,1)) -> 0 | H12: =SUMIFS(CAJA!D:D,CAJA!G:G,"VARIO",CAJA!H:H,"PAGO*",CAJA!B:B,A12) -> 0 | I12: =G12-H12 -> 0 | J12: =IF(I12>D12,"MOROSO",IF(I12>0,"COBRAR CUOTA","NORMAL")) -> NORMAL | M12: 10000 | N12: 18 | O12: 1080
G13: =B13+D13*(IF(12*(+LEFT(MID(CELL("nombrearchivo",A12),FIND(".xlsx",CELL("nombrearchivo",A12))-4,4),2)-RIGHT(YEAR(F13),2))+RIGHT(MID(CELL("nombrearchivo",A12),FIND(".xlsx",CELL("nombrearchivo",A12))-4,4),2)-MONTH(F13)>E13,0,1)) -> 0 | H13: =SUMIFS(CAJA!D:D,CAJA!G:G,"VARIO",CAJA!H:H,"PAGO*",CAJA!B:B,A13) -> 0 | I13: =G13-H13 -> 0 | J13: =IF(I13>D13,"MOROSO",IF(I13>0,"COBRAR CUOTA","NORMAL")) -> NORMAL | M13: 15000 | N13: 18 | O13: 1620
G14: =B14+D14*(IF(12*(+LEFT(MID(CELL("nombrearchivo",A13),FIND(".xlsx",CELL("nombrearchivo",A13))-4,4),2)-RIGHT(YEAR(F14),2))+RIGHT(MID(CELL("nombrearchivo",A13),FIND(".xlsx",CELL("nombrearchivo",A13))-4,4),2)-MONTH(F14)>E14,0,1)) -> 0 | H14: =SUMIFS(CAJA!D:D,CAJA!G:G,"VARIO",CAJA!H:H,"PAGO*",CAJA!B:B,A14) -> 0 | I14: =G14-H14 -> 0 | J14: =IF(I14>D14,"MOROSO",IF(I14>0,"COBRAR CUOTA","NORMAL")) -> NORMAL | M14: 20000 | N14: 18 | O14: 2160
G15: =B15+D15*(IF(12*(+LEFT(MID(CELL("nombrearchivo",A14),FIND(".xlsx",CELL("nombrearchivo",A14))-4,4),2)-RIGHT(YEAR(F15),2))+RIGHT(MID(CELL("nombrearchivo",A14),FIND(".xlsx",CELL("nombrearchivo",A14))-4,4),2)-MONTH(F15)>E15,0,1)) -> 0 | H15: =SUMIFS(CAJA!D:D,CAJA!G:G,"VARIO",CAJA!H:H,"PAGO*",CAJA!B:B,A15) -> 0 | I15: =G15-H15 -> 0 | J15: =IF(I15>D15,"MOROSO",IF(I15>0,"COBRAR CUOTA","NORMAL")) -> NORMAL
G16: =B16+D16*(IF(12*(+LEFT(MID(CELL("nombrearchivo",A15),FIND(".xlsx",CELL("nombrearchivo",A15))-4,4),2)-RIGHT(YEAR(F16),2))+RIGHT(MID(CELL("nombrearchivo",A15),FIND(".xlsx",CELL("nombrearchivo",A15))-4,4),2)-MONTH(F16)>E16,0,1)) -> 0 | H16: =SUMIFS(CAJA!D:D,CAJA!G:G,"VARIO",CAJA!H:H,"PAGO*",CAJA!B:B,A16) -> 0 | I16: =G16-H16 -> 0 | J16: =IF(I16>D16,"MOROSO",IF(I16>0,"COBRAR CUOTA","NORMAL")) -> NORMAL
G17: =B17+D17*(IF(12*(+LEFT(MID(CELL("nombrearchivo",A16),FIND(".xlsx",CELL("nombrearchivo",A16))-4,4),2)-RIGHT(YEAR(F17),2))+RIGHT(MID(CELL("nombrearchivo",A16),FIND(".xlsx",CELL("nombrearchivo",A16))-4,4),2)-MONTH(F17)>E17,0,1)) -> 0 | H17: =SUMIFS(CAJA!D:D,CAJA!G:G,"VARIO",CAJA!H:H,"PAGO*",CAJA!B:B,A17) -> 0 | I17: =G17-H17 -> 0 | J17: =IF(I17>D17,"MOROSO",IF(I17>0,"COBRAR CUOTA","NORMAL")) -> NORMAL
G18: =B18+D18*(IF(12*(+LEFT(MID(CELL("nombrearchivo",A17),FIND(".xlsx",CELL("nombrearchivo",A17))-4,4),2)-RIGHT(YEAR(F18),2))+RIGHT(MID(CELL("nombrearchivo",A17),FIND(".xlsx",CELL("nombrearchivo",A17))-4,4),2)-MONTH(F18)>E18,0,1)) -> 0 | H18: =SUMIFS(CAJA!D:D,CAJA!G:G,"VARIO",CAJA!H:H,"PAGO*",CAJA!B:B,A18) -> 0 | I18: =G18-H18 -> 0 | J18: =IF(I18>D18,"MOROSO",IF(I18>0,"COBRAR CUOTA","NORMAL")) -> NORMAL
G19: =B19+D19*(IF(12*(+LEFT(MID(CELL("nombrearchivo",A18),FIND(".xlsx",CELL("nombrearchivo",A18))-4,4),2)-RIGHT(YEAR(F19),2))+RIGHT(MID(CELL("nombrearchivo",A18),FIND(".xlsx",CELL("nombrearchivo",A18))-4,4),2)-MONTH(F19)>E19,0,1)) -> 0 | H19: =SUMIFS(CAJA!D:D,CAJA!G:G,"VARIO",CAJA!H:H,"PAGO*",CAJA!B:B,A19) -> 0 | I19: =G19-H19 -> 0 | J19: =IF(I19>D19,"MOROSO",IF(I19>0,"COBRAR CUOTA","NORMAL")) -> NORMAL
G20: =B20+D20*(IF(12*(+LEFT(MID(CELL("nombrearchivo",A19),FIND(".xlsx",CELL("nombrearchivo",A19))-4,4),2)-RIGHT(YEAR(F20),2))+RIGHT(MID(CELL("nombrearchivo",A19),FIND(".xlsx",CELL("nombrearchivo",A19))-4,4),2)-MONTH(F20)>E20,0,1)) -> 0 | H20: =SUMIFS(CAJA!D:D,CAJA!G:G,"VARIO",CAJA!H:H,"PAGO*",CAJA!B:B,A20) -> 0 | I20: =G20-H20 -> 0 | J20: =IF(I20>D20,"MOROSO",IF(I20>0,"COBRAR CUOTA","NORMAL")) -> NORMAL
G21: =B21+D21*(IF(12*(+LEFT(MID(CELL("nombrearchivo",A20),FIND(".xlsx",CELL("nombrearchivo",A20))-4,4),2)-RIGHT(YEAR(F21),2))+RIGHT(MID(CELL("nombrearchivo",A20),FIND(".xlsx",CELL("nombrearchivo",A20))-4,4),2)-MONTH(F21)>E21,0,1)) -> 0 | H21: =SUMIFS(CAJA!D:D,CAJA!G:G,"VARIO",CAJA!H:H,"PAGO*",CAJA!B:B,A21) -> 0 | I21: =G21-H21 -> 0 | J21: =IF(I21>D21,"MOROSO",IF(I21>0,"COBRAR CUOTA","NORMAL")) -> NORMAL
G22: =B22+D22*(IF(12*(+LEFT(MID(CELL("nombrearchivo",A21),FIND(".xlsx",CELL("nombrearchivo",A21))-4,4),2)-RIGHT(YEAR(F22),2))+RIGHT(MID(CELL("nombrearchivo",A21),FIND(".xlsx",CELL("nombrearchivo",A21))-4,4),2)-MONTH(F22)>E22,0,1)) -> 0 | H22: =SUMIFS(CAJA!D:D,CAJA!G:G,"VARIO",CAJA!H:H,"PAGO*",CAJA!B:B,A22) -> 0 | I22: =G22-H22 -> 0 | J22: =IF(I22>D22,"MOROSO",IF(I22>0,"COBRAR CUOTA","NORMAL")) -> NORMAL
G23: =B23+D23*(IF(12*(+LEFT(MID(CELL("nombrearchivo",A22),FIND(".xlsx",CELL("nombrearchivo",A22))-4,4),2)-RIGHT(YEAR(F23),2))+RIGHT(MID(CELL("nombrearchivo",A22),FIND(".xlsx",CELL("nombrearchivo",A22))-4,4),2)-MONTH(F23)>E23,0,1)) -> 0 | H23: =SUMIFS(CAJA!D:D,CAJA!G:G,"VARIO",CAJA!H:H,"PAGO*",CAJA!B:B,A23) -> 0 | I23: =G23-H23 -> 0 | J23: =IF(I23>D23,"MOROSO",IF(I23>0,"COBRAR CUOTA","NORMAL")) -> NORMAL
G24: =B24+D24*(IF(12*(+LEFT(MID(CELL("nombrearchivo",A23),FIND(".xlsx",CELL("nombrearchivo",A23))-4,4),2)-RIGHT(YEAR(F24),2))+RIGHT(MID(CELL("nombrearchivo",A23),FIND(".xlsx",CELL("nombrearchivo",A23))-4,4),2)-MONTH(F24)>E24,0,1)) -> 0 | H24: =SUMIFS(CAJA!D:D,CAJA!G:G,"VARIO",CAJA!H:H,"PAGO*",CAJA!B:B,A24) -> 0 | I24: =G24-H24 -> 0 | J24: =IF(I24>D24,"MOROSO",IF(I24>0,"COBRAR CUOTA","NORMAL")) -> NORMAL
G25: =B25+D25*(IF(12*(+LEFT(MID(CELL("nombrearchivo",A24),FIND(".xlsx",CELL("nombrearchivo",A24))-4,4),2)-RIGHT(YEAR(F25),2))+RIGHT(MID(CELL("nombrearchivo",A24),FIND(".xlsx",CELL("nombrearchivo",A24))-4,4),2)-MONTH(F25)>E25,0,1)) -> 0 | H25: =SUMIFS(CAJA!D:D,CAJA!G:G,"VARIO",CAJA!H:H,"PAGO*",CAJA!B:B,A25) -> 0 | I25: =G25-H25 -> 0 | J25: =IF(I25>D25,"MOROSO",IF(I25>0,"COBRAR CUOTA","NORMAL")) -> NORMAL
G26: =B26+D26*(IF(12*(+LEFT(MID(CELL("nombrearchivo",A25),FIND(".xlsx",CELL("nombrearchivo",A25))-4,4),2)-RIGHT(YEAR(F26),2))+RIGHT(MID(CELL("nombrearchivo",A25),FIND(".xlsx",CELL("nombrearchivo",A25))-4,4),2)-MONTH(F26)>E26,0,1)) -> 0 | H26: =SUMIFS(CAJA!D:D,CAJA!G:G,"VARIO",CAJA!H:H,"PAGO*",CAJA!B:B,A26) -> 0 | I26: =G26-H26 -> 0 | J26: =IF(I26>D26,"MOROSO",IF(I26>0,"COBRAR CUOTA","NORMAL")) -> NORMAL
... G29: =B29+D29*(IF(12*(+LEFT(MID(CELL("nombrearchivo",A28),FIND(".xlsx",CELL("nombrearchivo",A28))-4,4),2)-RIGHT(YEAR(F29),2))+RIGHT(MID(CELL("nombrearchivo",A28),FIND(".xlsx",CELL("nombrearchivo",A28))-4,4),2)-MONTH(F29)>E29,0,1)) -> 0 | H29: =SUMIFS(CAJA!D:D,CAJA!G:G,"VARIO",CAJA!H:H,"PAGO*",CAJA!B:B,A29) -> 0 | I29: =G29-H29 -> 0 | J29: =IF(I29>D29,"MOROSO",IF(I29>0,"COBRAR CUOTA","NORMAL")) -> NORMAL

Sheet Saldos
A1: =IF(D1="",TODAY(),D1) -> 45545 | B1: Actual | C1: Inicial
A2: EFE | B2: =SUMIFS(CAJA!D:D,CAJA!I:I,"CAJA",CAJA!J:J,A2,CAJA!A:A,"<=" & A1)-SUMIFS(CAJA!E:E,CAJA!I:I,"CAJA",CAJA!J:J,A2,CAJA!A:A,"<=" & A1)+C2 -> 406971.84 | C2: 909448.89
A3: CHE | B3: =SUMIFS(CAJA!D:D,CAJA!J:J,A3,CAJA!A:A,"<=" & $A$1)-SUMIFS(CAJA!E:E,CAJA!J:J,A3,CAJA!A:A,"<=" & $A$1)+C3 -> 0
A4: CC | B4: =SUMIFS(CAJA!D:D,CAJA!J:J,A4,CAJA!A:A,"<=" & $A$1)-SUMIFS(CAJA!D:D,CAJA!G:G,"VARIO",CAJA!H:H,"PAGOCC",CAJA!A:A,"<=" & $A$1)+C4 -> 0
A5: MEN | B5: =SUMIFS(CAJA!D:D,CAJA!I:I,A5,CAJA!A:A,"<=" & $A$1)-SUMIFS(CAJA!D:D,CAJA!G:G,"VARIO",CAJA!H:H,"PAGOMEN",CAJA!A:A,"<=" & $A$1)+C5 -> 0
A6: TDC | B6: =SUMIFS(CAJA!D:D,CAJA!J:J,A6,CAJA!A:A,"<=" & $A$1)-SUMIFS(CAJA!E:E,CAJA!J:J,A6,CAJA!A:A,"<=" & $A$1)+C6 -> 0
A7: Caja | B7: =SUMIFS(CAJA!D:D,CAJA!G:G,"ACCESORIO",CAJA!A:A,"=" & $D$8) -> 0 | D7: 43019
A8: CajaAcc | B8: =SUMIFS(CajaAcc!D:D,CajaAcc!A:A,"=" & $D$7) -> 0 | D8: 43019
A9: V24 | B9: =SUMIFS(CAJA!D:D,CAJA!G:G,A9,CAJA!A:A,"<=" & $A$1)-SUMIFS(CAJA!E:E,CAJA!G:G,A9,CAJA!A:A,"<=" & $A$1)+C9 -> 0
A10: Orga | B10: =SUMIFS(CAJA!D:D,CAJA!G:G,A10,CAJA!A:A,"<=" & $A$1)-SUMIFS(CAJA!E:E,CAJA!G:G,A10,CAJA!A:A,"<=" & $A$1)+C10 -> 3440

Sheet Gastos
A1: GASTO | B1: =SUMIF(CAJA!$G$4:$G$2493,"GASTO",CAJA!$E$4:$E$2493) -> 973441.05 | C1: Presupuesto | D1: Control
A2: ALQUILER | B2: =SUMIFS(CAJA!$E$4:$E$2493,CAJA!$G$4:$G$2493,"GASTO",CAJA!$H$4:$H$2493,A2) -> 0 | D2: =IF(C2<B2,"EXCEDIDO","")
A3: AUTOMOTOR | B3: =SUMIFS(CAJA!$E$4:$E$2493,CAJA!$G$4:$G$2493,"GASTO",CAJA!$H$4:$H$2493,A3) -> 2000 | D3: =IF(C3<B3,"EXCEDIDO","") -> EXCEDIDO
A4: BANCARIOS | B4: =SUMIFS(CAJA!$E$4:$E$2493,CAJA!$G$4:$G$2493,"GASTO",CAJA!$H$4:$H$2493,A4) -> 0 | D4: =IF(C4<B4,"EXCEDIDO","")
A5: COMISION | B5: =SUMIFS(CAJA!$E$4:$E$2493,CAJA!$G$4:$G$2493,"GASTO",CAJA!$H$4:$H$2493,A5) -> -6820 | D5: =IF(C5<B5,"EXCEDIDO","")
A6: FLETE | B6: =SUMIFS(CAJA!$E$4:$E$2493,CAJA!$G$4:$G$2493,"GASTO",CAJA!$H$4:$H$2493,A6) -> 3400 | D6: =IF(C6<B6,"EXCEDIDO","") -> EXCEDIDO
A7: SERVICIOS | B7: =SUMIFS(CAJA!$E$4:$E$2493,CAJA!$G$4:$G$2493,"GASTO",CAJA!$H$4:$H$2493,A7) -> 39186.87 | D7: =IF(C7<B7,"EXCEDIDO","") -> EXCEDIDO
A8: LIBRERÍA | B8: =SUMIFS(CAJA!$E$4:$E$2493,CAJA!$G$4:$G$2493,"GASTO",CAJA!$H$4:$H$2493,A8) -> 0 | D8: =IF(C8<B8,"EXCEDIDO","")
A9: LIMPIEZA | B9: =SUMIFS(CAJA!$E$4:$E$2493,CAJA!$G$4:$G$2493,"GASTO",CAJA!$H$4:$H$2493,A9) -> 17600 | D9: =IF(C9<B9,"EXCEDIDO","") -> EXCEDIDO
B10: =SUMIFS(CAJA!$E$4:$E$2493,CAJA!$G$4:$G$2493,"GASTO",CAJA!$H$4:$H$2493,A10) -> 0 | D10: =IF(C10<B10,"EXCEDIDO","")
A11: PUBLICIDAD | B11: =SUMIFS(CAJA!$E$4:$E$2493,CAJA!$G$4:$G$2493,"GASTO",CAJA!$H$4:$H$2493,A11) -> 0 | D11: =IF(C11<B11,"EXCEDIDO","")
A12: SUELDOS | B12: =SUMIFS(CAJA!$E$4:$E$2493,CAJA!$G$4:$G$2493,"GASTO",CAJA!$H$4:$H$2493,A12) -> 885200 | D12: =IF(C12<B12,"EXCEDIDO","") -> EXCEDIDO
B13: =SUMIFS(CAJA!$E$4:$E$2493,CAJA!$G$4:$G$2493,"GASTO",CAJA!$H$4:$H$2493,A13) -> 0 | D13: =IF(C13<B13,"EXCEDIDO","")
A14: VARIOS | B14: =SUMIFS(CAJA!$E$4:$E$2493,CAJA!$G$4:$G$2493,"GASTO",CAJA!$H$4:$H$2493,A14) -> 32874.18 | D14: =IF(C14<B14,"EXCEDIDO","") -> EXCEDIDO
A15: VIATICOS | B15: =SUMIFS(CAJA!$E$4:$E$2493,CAJA!$G$4:$G$2493,"GASTO",CAJA!$H$4:$H$2493,A15) -> 0 | D15: =IF(C15<B15,"EXCEDIDO","")
A16: SEGURIDAD | B16: =SUMIFS(CAJA!$E$4:$E$2493,CAJA!$G$4:$G$2493,"GASTO",CAJA!$H$4:$H$2493,A16) -> 0 | D16: =IF(C16<B16,"EXCEDIDO","")
A17: MUNICIPAL | B17: =SUMIFS(CAJA!$E$4:$E$2493,CAJA!$G$4:$G$2493,"GASTO",CAJA!$H$4:$H$2493,A17) -> 0 | D17: =IF(C17<B17,"EXCEDIDO","")
B18: =SUMIFS(CAJA!$E$4:$E$2493,CAJA!$G$4:$G$2493,"GASTO",CAJA!$H$4:$H$2493,A18) -> 0 | D18: =IF(C18<B18,"EXCEDIDO","")
A19: TOTAL | B19: =SUM(B2:B18) -> 973441.05 | D19: =IF(C19<B19,"EXCEDIDO","") -> EXCEDIDO
A20: =IF(SUMIF(CAJA!$G$4:$G$2493,"GASTO",CAJA!$D$4:$D$2493)=0,"BIEN","HAY ERRORES") -> BIEN | B20: =IF(ROUND($B$1-$B$19,0)=0,"BIEN","HAY ERRORES") -> BIEN
A21: Ingresos | B21: Validacion

Sheet Equipos
B1: =IF(-SUMIFS(CAJA!F:F,CAJA!G:G,"PROPIO",CAJA!H:H,"<>SIM-CAR")-SUM(B5:B97)+SUM(C5:C97)=0,"BIEN","HAY ERRORES") -> BIEN | C1: =IF(SUMIF(CAJA!$G$4:$G$2493,"HOMO",CAJA!$F$4:$F$2493)-SUM(#REF!)+SUM(#REF!)=0,"HOMOLOGADOS BIEN","HAY ERRORES EN HOMOLOGADOS") -> #REF! | D1: =IF(-SUMIF(CAJA!$G$4:$G$2493,"KIT",CAJA!$F$4:$F$2493)-SUM(D5:D97)+SUM(E5:E97)=0,"BIEN","HAY ERRORES") -> BIEN | E1: =IF(SUMIF(CAJA!$G$4:$G$2493,"HOMO",CAJA!$F$4:$F$2493)-SUM(#REF!)+SUM(#REF!)=0,"HOMOLOGADOS BIEN","HAY ERRORES EN HOMOLOGADOS") -> #REF!
B2: PROPIOS | D2: KITS
A3: Equipo | B3: Actual | C3: Inicial | D3: Actual | E3: Inicial
A4: SIM-CAR | B4: =-SUMIFS(CAJA!$F$4:$F$2493,CAJA!$G$4:$G$2493,"PROPIO",CAJA!$H$4:$H$2493,$A4)-SUMIFS(CAJA!F:F,CAJA!G:G,"?280")-SUMIFS(CAJA!F:F,CAJA!G:G,"?1G")-SUMIFS(CAJA!F:F,CAJA!G:G,"?3G")-SUMIFS(CAJA!F:F,CAJA!G:G,"?5G")-SUMIFS(CAJA!F:F,CAJA!G:G,"?8G")-SUMIFS(CAJA!F:F,CAJA!G:G,"?15G")-SUMIFS(CAJA!F:F,CAJA!G:G,"?25G")-SUMIFS(CAJA!F:F,CAJA!G:G,"imr")-SUMIFS(CAJA!F:F,CAJA!G:G,"imp")-SUMIFS(CAJA!F:F,CAJA!G:G,"prepaga")-SUMIFS(CAJA!F:F,CAJA!G:G,"MIG")+C4 -> 128 | C4: 323 | D4: =-SUMIFS(CAJA!$F$4:$F$2493,CAJA!$G$4:$G$2493,"KIT",CAJA!$H$4:$H$2493,$A4)+E4 -> 0 | F4: =IF(SUM(B4:E4) = 0,"VACIA","")
A5: SIM-1175 | B5: =-SUMIFS(CAJA!$F$4:$F$2493,CAJA!$G$4:$G$2493,"PROPIO",CAJA!$H$4:$H$2493,$A5)+C5 -> 16 | C5: 26 | D5: =-SUMIFS(CAJA!$F$4:$F$2493,CAJA!$G$4:$G$2493,"KIT",CAJA!$H$4:$H$2493,$A5)+E5 -> 0 | F5: =35600+19100+36900+32100+92000+96000+2000+21500+2000+1500+350+480+160+171+1111 -> 340972
A6: A-A5H | B6: =-SUMIFS(CAJA!$F$4:$F$2493,CAJA!$G$4:$G$2493,"PROPIO",CAJA!$H$4:$H$2493,$A6)+C6 -> 0 | D6: =-SUMIFS(CAJA!$F$4:$F$2493,CAJA!$G$4:$G$2493,"KIT",CAJA!$H$4:$H$2493,$A6)+E6 -> 0 | F6: =IF(SUM(B6:E6) = 0,"VACIA","") -> VACIA
A7: AIO-PBARW | B7: =-SUMIFS(CAJA!$F$4:$F$2493,CAJA!$G$4:$G$2493,"PROPIO",CAJA!$H$4:$H$2493,$A7)+C7 -> 0 | D7: =-SUMIFS(CAJA!$F$4:$F$2493,CAJA!$G$4:$G$2493,"KIT",CAJA!$H$4:$H$2493,$A7)+E7 -> 0 | F7: =IF(SUM(B7:E7) = 0,"VACIA","") -> VACIA
A8: AIO-PBARW18 | B8: =-SUMIFS(CAJA!$F$4:$F$2493,CAJA!$G$4:$G$2493,"PROPIO",CAJA!$H$4:$H$2493,$A8)+C8 -> 0 | D8: =-SUMIFS(CAJA!$F$4:$F$2493,CAJA!$G$4:$G$2493,"KIT",CAJA!$H$4:$H$2493,$A8)+E8 -> 0 | F8: =IF(SUM(B8:E8) = 0,"VACIA","") -> VACIA
A9: IN-ANCT300 | B9: =-SUMIFS(CAJA!$F$4:$F$2493,CAJA!$G$4:$G$2493,"PROPIO",CAJA!$H$4:$H$2493,$A9)+C9 -> 0 | D9: =-SUMIFS(CAJA!$F$4:$F$2493,CAJA!$G$4:$G$2493,"KIT",CAJA!$H$4:$H$2493,$A9)+E9 -> 0 | F9: =IF(SUM(B9:E9) = 0,"VACIA","") -> VACIA
A10: IN-NDT4000TW | B10: =-SUMIFS(CAJA!$F$4:$F$2493,CAJA!$G$4:$G$2493,"PROPIO",CAJA!$H$4:$H$2493,$A10)+C10 -> 0 | D10: =-SUMIFS(CAJA!$F$4:$F$2493,CAJA!$G$4:$G$2493,"KIT",CAJA!$H$4:$H$2493,$A10)+E10 -> 0 | F10: =IF(SUM(B10:E10) = 0,"VACIA","") -> VACIA
A11: M-E13 | B11: =-SUMIFS(CAJA!$F$4:$F$2493,CAJA!$G$4:$G$2493,"PROPIO",CAJA!$H$4:$H$2493,$A11)+C11 -> 0 | D11: =-SUMIFS(CAJA!$F$4:$F$2493,CAJA!$G$4:$G$2493,"KIT",CAJA!$H$4:$H$2493,$A11)+E11 -> 0 | F11: =IF(SUM(B11:E11) = 0,"VACIA","") -> VACIA
A12: M-E22 | B12: =-SUMIFS(CAJA!$F$4:$F$2493,CAJA!$G$4:$G$2493,"PROPIO",CAJA!$H$4:$H$2493,$A12)+C12 -> 0 | D12: =-SUMIFS(CAJA!$F$4:$F$2493,CAJA!$G$4:$G$2493,"KIT",CAJA!$H$4:$H$2493,$A12)+E12 -> 0 | F12: =IF(SUM(B12:E12) = 0,"VACIA","") -> VACIA
A13: M-E32 | B13: =-SUMIFS(CAJA!$F$4:$F$2493,CAJA!$G$4:$G$2493,"PROPIO",CAJA!$H$4:$H$2493,$A13)+C13 -> 0 | D13: =-SUMIFS(CAJA!$F$4:$F$2493,CAJA!$G$4:$G$2493,"KIT",CAJA!$H$4:$H$2493,$A13)+E13 -> 0 | F13: =IF(SUM(B13:E13) = 0,"VACIA","") -> VACIA
A14: M-G22 | B14: =-SUMIFS(CAJA!$F$4:$F$2493,CAJA!$G$4:$G$2493,"PROPIO",CAJA!$H$4:$H$2493,$A14)+C14 -> 0 | D14: =-SUMIFS(CAJA!$F$4:$F$2493,CAJA!$G$4:$G$2493,"KIT",CAJA!$H$4:$H$2493,$A14)+E14 -> 0 | F14: =IF(SUM(B14:E14) = 0,"VACIA","") -> VACIA
A15: M-G32 | B15: =-SUMIFS(CAJA!$F$4:$F$2493,CAJA!$G$4:$G$2493,"PROPIO",CAJA!$H$4:$H$2493,$A15)+C15 -> 0 | D15: =-SUMIFS(CAJA!$F$4:$F$2493,CAJA!$G$4:$G$2493,"KIT",CAJA!$H$4:$H$2493,$A15)+E15 -> 0 | F15: =IF(SUM(B15:E15) = 0,"VACIA","") -> VACIA
A16: M-G42 | B16: =-SUMIFS(CAJA!$F$4:$F$2493,CAJA!$G$4:$G$2493,"PROPIO",CAJA!$H$4:$H$2493,$A16)+C16 -> 0 | D16: =-SUMIFS(CAJA!$F$4:$F$2493,CAJA!$G$4:$G$2493,"KIT",CAJA!$H$4:$H$2493,$A16)+E16 -> 0 | F16: =IF(SUM(B16:E16) = 0,"VACIA","") -> VACIA
A17: M-ME40 | B17: =-SUMIFS(CAJA!$F$4:$F$2493,CAJA!$G$4:$G$2493,"PROPIO",CAJA!$H$4:$H$2493,$A17)+C17 -> 0 | D17: =-SUMIFS(CAJA!$F$4:$F$2493,CAJA!$G$4:$G$2493,"KIT",CAJA!$H$4:$H$2493,$A17)+E17 -> 0 | F17: =IF(SUM(B17:E17) = 0,"VACIA","") -> VACIA
... A37: S-A23 | B37: =-SUMIFS(CAJA!$F$4:$F$2493,CAJA!$G$4:$G$2493,"PROPIO",CAJA!$H$4:$H$2493,$A37)+C37 -> 0 | D37: =-SUMIFS(CAJA!$F$4:$F$2493,CAJA!$G$4:$G$2493,"KIT",CAJA!$H$4:$H$2493,$A37)+E37 -> 0 | F37: =IF(SUM(B37:E37) = 0,"VACIA","") -> VACIA
A38: S-A23G5 | B38: =-SUMIFS(CAJA!$F$4:$F$2493,CAJA!$G$4:$G$2493,"PROPIO",CAJA!$H$4:$H$2493,$A38)+C38 -> 1 | C38: 1 | D38: =-SUMIFS(CAJA!$F$4:$F$2493,CAJA!$G$4:$G$2493,"KIT",CAJA!$H$4:$H$2493,$A38)+E38 -> 0 | F38: =IF(SUM(B38:E38) = 0,"VACIA","")
A39: S-A24 | B39: =-SUMIFS(CAJA!$F$4:$F$2493,CAJA!$G$4:$G$2493,"PROPIO",CAJA!$H$4:$H$2493,$A39)+C39 -> 0 | D39: =-SUMIFS(CAJA!$F$4:$F$2493,CAJA!$G$4:$G$2493,"KIT",CAJA!$H$4:$H$2493,$A39)+E39 -> 0 | F39: =IF(SUM(B39:E39) = 0,"VACIA","") -> VACIA
A40: S-A33 | B40: =-SUMIFS(CAJA!$F$4:$F$2493,CAJA!$G$4:$G$2493,"PROPIO",CAJA!$H$4:$H$2493,$A40)+C40 -> 0 | D40: =-SUMIFS(CAJA!$F$4:$F$2493,CAJA!$G$4:$G$2493,"KIT",CAJA!$H$4:$H$2493,$A40)+E40 -> 0 | F40: =IF(SUM(B40:E40) = 0,"VACIA","") -> VACIA
A41: S-A34G1 | B41: =-SUMIFS(CAJA!$F$4:$F$2493,CAJA!$G$4:$G$2493,"PROPIO",CAJA!$H$4:$H$2493,$A41)+C41 -> 0 | D41: =-SUMIFS(CAJA!$F$4:$F$2493,CAJA!$G$4:$G$2493,"KIT",CAJA!$H$4:$H$2493,$A41)+E41 -> 0 | F41: =IF(SUM(B41:E41) = 0,"VACIA","") -> VACIA
A42: S-A34G2 | B42: =-SUMIFS(CAJA!$F$4:$F$2493,CAJA!$G$4:$G$2493,"PROPIO",CAJA!$H$4:$H$2493,$A42)+C42 -> 0 | D42: =-SUMIFS(CAJA!$F$4:$F$2493,CAJA!$G$4:$G$2493,"KIT",CAJA!$H$4:$H$2493,$A42)+E42 -> 0 | F42: =IF(SUM(B42:E42) = 0,"VACIA","") -> VACIA
A43: S-A52 | B43: =-SUMIFS(CAJA!$F$4:$F$2493,CAJA!$G$4:$G$2493,"PROPIO",CAJA!$H$4:$H$2493,$A43)+C43 -> 0 | D43: =-SUMIFS(CAJA!$F$4:$F$2493,CAJA!$G$4:$G$2493,"KIT",CAJA!$H$4:$H$2493,$A43)+E43 -> 0 | F43: =IF(SUM(B43:E43) = 0,"VACIA","") -> VACIA
A44: S-A52S | B44: =-SUMIFS(CAJA!$F$4:$F$2493,CAJA!$G$4:$G$2493,"PROPIO",CAJA!$H$4:$H$2493,$A44)+C44 -> 0 | D44: =-SUMIFS(CAJA!$F$4:$F$2493,CAJA!$G$4:$G$2493,"KIT",CAJA!$H$4:$H$2493,$A44)+E44 -> 0 | F44: =IF(SUM(B44:E44) = 0,"VACIA","") -> VACIA
A45: S-A53 | B45: =-SUMIFS(CAJA!$F$4:$F$2493,CAJA!$G$4:$G$2493,"PROPIO",CAJA!$H$4:$H$2493,$A45)+C45 -> 0 | D45: =-SUMIFS(CAJA!$F$4:$F$2493,CAJA!$G$4:$G$2493,"KIT",CAJA!$H$4:$H$2493,$A45)+E45 -> 0 | F45: =IF(SUM(B45:E45) = 0,"VACIA","") -> VACIA
A46: S-A54G1 | B46: =-SUMIFS(CAJA!$F$4:$F$2493,CAJA!$G$4:$G$2493,"PROPIO",CAJA!$H$4:$H$2493,$A46)+C46 -> 0 | D46: =-SUMIFS(CAJA!$F$4:$F$2493,CAJA!$G$4:$G$2493,"KIT",CAJA!$H$4:$H$2493,$A46)+E46 -> 0 | F46: =IF(SUM(B46:E46) = 0,"VACIA","") -> VACIA
A47: S-A54G2 | B47: =-SUMIFS(CAJA!$F$4:$F$2493,CAJA!$G$4:$G$2493,"PROPIO",CAJA!$H$4:$H$2493,$A47)+C47 -> 0 | D47: =-SUMIFS(CAJA!$F$4:$F$2493,CAJA!$G$4:$G$2493,"KIT",CAJA!$H$4:$H$2493,$A47)+E47 -> 0 | F47: =IF(SUM(B47:E47) = 0,"VACIA","") -> VACIA
A48: S-A72 | B48: =-SUMIFS(CAJA!$F$4:$F$2493,CAJA!$G$4:$G$2493,"PROPIO",CAJA!$H$4:$H$2493,$A48)+C48 -> 0 | D48: =-SUMIFS(CAJA!$F$4:$F$2493,CAJA!$G$4:$G$2493,"KIT",CAJA!$H$4:$H$2493,$A48)+E48 -> 0 | F48: =IF(SUM(B48:E48) = 0,"VACIA","") -> VACIA
A49: S-M13 | B49: =-SUMIFS(CAJA!$F$4:$F$2493,CAJA!$G$4:$G$2493,"PROPIO",CAJA!$H$4:$H$2493,$A49)+C49 -> 0 | D49: =-SUMIFS(CAJA!$F$4:$F$2493,CAJA!$G$4:$G$2493,"KIT",CAJA!$H$4:$H$2493,$A49)+E49 -> 0 | F49: =IF(SUM(B49:E49) = 0,"VACIA","") -> VACIA
A50: S-M23 | B50: =-SUMIFS(CAJA!$F$4:$F$2493,CAJA!$G$4:$G$2493,"PROPIO",CAJA!$H$4:$H$2493,$A50)+C50 -> 0 | D50: =-SUMIFS(CAJA!$F$4:$F$2493,CAJA!$G$4:$G$2493,"KIT",CAJA!$H$4:$H$2493,$A50)+E50 -> 0 | F50: =IF(SUM(B50:E50) = 0,"VACIA","") -> VACIA
... A53: SM-SFIR220 | B53: =-SUMIFS(CAJA!$F$4:$F$2493,CAJA!$G$4:$G$2493,"PROPIO",CAJA!$H$4:$H$2493,$A53)+C53 -> 0 | D53: =-SUMIFS(CAJA!$F$4:$F$2493,CAJA!$G$4:$G$2493,"KIT",CAJA!$H$4:$H$2493,$A53)+E53 -> 0 | F53: =IF(SUM(B53:E53) = 0,"VACIA","") -> VACIA
A54: SM-SM150 | B54: =-SUMIFS(CAJA!$F$4:$F$2493,CAJA!$G$4:$G$2493,"PROPIO",CAJA!$H$4:$H$2493,$A54)+C54 -> 1 | C54: 1 | D54: =-SUMIFS(CAJA!$F$4:$F$2493,CAJA!$G$4:$G$2493,"KIT",CAJA!$H$4:$H$2493,$A54)+E54 -> 0 | F54: =IF(SUM(B54:E54) = 0,"VACIA","")
A55: SM-SR870 | B55: =-SUMIFS(CAJA!$F$4:$F$2493,CAJA!$G$4:$G$2493,"PROPIO",CAJA!$H$4:$H$2493,$A55)+C55 -> 0 | D55: =-SUMIFS(CAJA!$F$4:$F$2493,CAJA!$G$4:$G$2493,"KIT",CAJA!$H$4:$H$2493,$A55)+E55 -> 0 | F55: =IF(SUM(B55:E55) = 0,"VACIA","") -> VACIA
A56: SM-XK10 | B56: =-SUMIFS(CAJA!$F$4:$F$2493,CAJA!$G$4:$G$2493,"PROPIO",CAJA!$H$4:$H$2493,$A56)+C56 -> 4 | C56: 4 | D56: =-SUMIFS(CAJA!$F$4:$F$2493,CAJA!$G$4:$G$2493,"KIT",CAJA!$H$4:$H$2493,$A56)+E56 -> 0 | F56: =IF(SUM(B56:E56) = 0,"VACIA","")
A57: SM-XL11 | B57: =-SUMIFS(CAJA!$F$4:$F$2493,CAJA!$G$4:$G$2493,"PROPIO",CAJA!$H$4:$H$2493,$A57)+C57 -> 0 | D57: =-SUMIFS(CAJA!$F$4:$F$2493,CAJA!$G$4:$G$2493,"KIT",CAJA!$H$4:$H$2493,$A57)+E57 -> 0 | F57: =IF(SUM(B57:E57) = 0,"VACIA","") -> VACIA
A58: SM-XMB6 | B58: =-SUMIFS(CAJA!$F$4:$F$2493,CAJA!$G$4:$G$2493,"PROPIO",CAJA!$H$4:$H$2493,$A58)+C58 -> 0 | D58: =-SUMIFS(CAJA!$F$4:$F$2493,CAJA!$G$4:$G$2493,"KIT",CAJA!$H$4:$H$2493,$A58)+E58 -> 0 | F58: =IF(SUM(B58:E58) = 0,"VACIA","") -> VACIA
A59: SM-XW01 | B59: =-SUMIFS(CAJA!$F$4:$F$2493,CAJA!$G$4:$G$2493,"PROPIO",CAJA!$H$4:$H$2493,$A59)+C59 -> 0 | D59: =-SUMIFS(CAJA!$F$4:$F$2493,CAJA!$G$4:$G$2493,"KIT",CAJA!$H$4:$H$2493,$A59)+E59 -> 0 | F59: =IF(SUM(B59:E59) = 0,"VACIA","") -> VACIA
A60: S-S20FE | B60: =-SUMIFS(CAJA!$F$4:$F$2493,CAJA!$G$4:$G$2493,"PROPIO",CAJA!$H$4:$H$2493,$A60)+C60 -> 0 | D60: =-SUMIFS(CAJA!$F$4:$F$2493,CAJA!$G$4:$G$2493,"KIT",CAJA!$H$4:$H$2493,$A60)+E60 -> 0 | F60: =IF(SUM(B60:E60) = 0,"VACIA","") -> VACIA
A61: S-S21FE | B61: =-SUMIFS(CAJA!$F$4:$F$2493,CAJA!$G$4:$G$2493,"PROPIO",CAJA!$H$4:$H$2493,$A61)+C61 -> 0 | D61: =-SUMIFS(CAJA!$F$4:$F$2493,CAJA!$G$4:$G$2493,"KIT",CAJA!$H$4:$H$2493,$A61)+E61 -> 0 | F61: =IF(SUM(B61:E61) = 0,"VACIA","") -> VACIA
...

Sheet Movimiento
A1: suc??? | B1: --->SUCURSALES
A2: NOMB. CLAVE | B2: ENTIDAD | C2: NOMBRE | D2: CALLE | E2: Nº | F2: P/D | G2: TELEFONO | H2: CIUDAD | I2: CP | J2: PROVINCIA | K2: RESP. | L2: CEL
A3: 1CONCORDIA | B3: 444167 | C3: CONCORDIA | G3: -- | H3: Concordia | I3: 3200 | J3: Entre Rios | K3: Carolina | L3: 3454038245
A4: 1ROJAS | C4: 1ROJAS | D4: 25 de Mayo | E4: 244 | G4: 02475-462592 | H4: Rojas | I4: 2705 | J4: Bs. As. | K4: Carla | L4: 2474465771
A5: 2COLON | C5: 2COLON | D5: Calle 20 | E5: 670 | G5: 02473-430867 | H5: Colon | I5: 2720 | J5: Bs. As. | K5: Monica | L5: 2473508608
A6: 2NICOLAS | B6: 493479 | C6: 2NICOLAS | D6: Mitre | E6: 169 | H6: San Nicolas | I6: 2900 | J6: Bs. As. | K6: Belen | L6: 3364562995
A7: 2ROJAS | C7: 2ROJAS | D7: Irigoyen | E7: 377 | G7: 02475-464827 | H7: Rojas | I7: 2705 | J7: Bs. As. | K7: Joana | L7: 2474494763
A8: 2ROSARIO | B8: -- | C8: 2ROSARIO | D8: San Luis | E8: 1697 | G8: -- | H8: Rosario | I8: 2000 | J8: Santa Fe | K8: Milagros | L8: 3413390134
A9: 3ROSARIO | B9: 505270 | C9: 3ROSARIO | D9: Juan J. Paso | E9: 2589 | H9: Rosario | I9: 2000 | J9: Santa Fe | K9: Magui | L9: 3412765552
A10: 5CORRIENTES | B10: 500089 | C10: CALL | H10: San Nicolas | I10: 2900 | J10: Bs As | K10: Ruth | L10: 3412126389
A11: 6CORRIENTES | B11: 540590 | C11: 6CORRIENTES | D11: Junin | E11: 1483 | H11: Corrientes | I11: 3400 | J11: Corrientes | K11: Romina | L11: 3624524604
A12: ACCESORIOS | B12: -- | C12: ACCESORIOS | D12: Gral. Paz | E12: 1242 | G12: 02477-420856 | H12: Pergamino | I12: 2700 | J12: Bs. As. | K12: Javier | L12: 2477567545
A13: ARRECIFES | C13: ARRECIFES | D13: Ricardo Gutierrez | E13: 656 | G13: 02478-455085 | H13: Arrecifes | I13: 2740 | J13: Bs. As. | K13: Monica | L13: 2478519274
A14: CENTENARIO | C14: CENTENARIO | D14: Juan B Justo | E14: 1902 | G14: 02477-445328 | H14: Pergamino | I14: 2700 | J14: Bs. As. | K14: Carolina | L14: 2477453769
A15: 1CONTABLE | B15: -- | C15: Contable | D15: General Paz | E15: 1240 | G15: 02477-420856 | H15: Pergamino | I15: 2700 | J15: Bs. As. | K15: Eugenia Ferrari | L15: 2477616088
A16: D1175 | C16: D1175 | D16: Rivadavia | E16: 2898 | G16: 011-5779-4293 | H16: C.A.B.A | I16: 1203 | J16: -- | K16: Gabriela | L16: 1160141914
A17: DCEN | C17: Dcen | D17: Gral. Paz | E17: 1242 | G17: 02477-420856 | H17: Pergamino | I17: 2700 | J17: Bs. As. | K17: Alberto | L17: 2477-699005
A18: DNICOLAS | B18: -- | C18: Dnicolas | D18: Nacion | E18: 155 | G18: 03461-434260 | H18: San Nicolas | I18: 2900 | J18: Bs. As. | K18: Lucrecia | L18: 3364495653
A19: GPAZ | B19: -- | C19: ADMINISTRACION | D19: Gral. Paz | E19: 1242 | G19: 02477-420856 | H19: Pergamino | I19: 2700 | J19: Bs. As. | K19: Eugenia Ferrari | L19: 2477-699005
A20: 3CONCORDIA | H20: CONCORDIA | J20: ENTRE RIOS | L20: 3455282659
A21: MERCEDES | B21: 506501 | C21: MERCEDES | D21: San Martin | E21: 897 | H21: Corrientes | I21: 3470 | J21: Corrientes | K21: Milagros | L21: 3773451929
A22: PEDRO | C22: PEDRO | D22: Mitre | E22: 970 | G22: 03329-421382 | H22: San Pedro | I22: 2930 | J22: Bs. As. | K22: Victoria | L22: 3329552626
A23: PRODUCTO | B23: -- | C23: PRODUCTO | D23: Gral. Paz | E23: 1242 | G23: 02477-420856 | H23: Pergamino | I23: 2700 | J23: Bs. As. | K23: Luz | L23: 2477329915
A24: SAMBA | B24: -- | C24: Samba | D24: Rivadavia | E24: 2898 | G24: 011-5779-4293 | H24: C.A.B.A | I24: 1203 | J24: -- | K24: Gabriela | L24: 1160141914
A25: SCEN | B25: -- | C25: Scen | D25: Juan B Justo | E25: 1902 | G25: 02477-445328 | H25: Pergamino | I25: 2700 | J25: Bs. As. | K25: Mariana Duarte | L25: 2477489315
A26: SNICOLAS | B26: -- | C26: Snicolas | D26: Nacion | E26: 155 | G26: 03461-434260 | H26: San Nicolas | I26: 2900 | J26: Bs. As. | K26: Belen | L26: 3364495653
A27: ZARATE | C27: ZARATE | D27: Justa Lima | E27: 642 | G27: 03487-435075 | H27: Zarate | I27: 2800 | J27: Bs. As. | K27: Ruth | L27: 3487535246
A28: PROVEEDOR
A29: CONCILIACION
A30: DISTRIBUCION
A31: REPARACION
A32: GARANTIAS
A33: PROMO
A34: DISCONTINUO
A35: CredicoopO | B35: Banco Credicoop. Cuenta Oslu Cuatro
A36: CredicoopOR | B36: Banco Crediccop. Cuenta Oslu Cuatro Recaudadora
A37: CredicoopC | B37: Banco Credicoop. Cuenta Emar Ceiba
A38: MacroOR | B38: Banco Macro. Cuenta Oslu Cuatro Recaudadora
A39: MacroC | B39: Banco Macro. Cuenta Emar Ceiba
A40: MacroT | B40: Banco Macro. Cuenta Comercializadora TEM
...

Sheet Ayuda
A1: Caja
A2: En H1 ingresar el nombre de la sucursal
A3: Modificando B2 (fecha) modifica la fecha del cálculo de efectivo, cheques, men y CC
A4: En J1 va el saldo inicial de efectivo. En J2 el saldo inicial de cheques. En L1 el saldo inicial de CC.
A5: Ingresando a M1 o M2 con el nombre utilizado en la columna detalle del cliente calcula el saldo de men (cuenta corriente del mes en curso) del mismo.
A6: Utilizarlo para en el cierre de mes dejar men en 0.
A8: Equipos propios son los celulares libres y las Sims.

Sheet Val
A1: BAF | B1: CAJA | C1: TRANSFER | D1: EFE | E1: VISA
A2: R1G | B2: MEN | C2: DIFERENCIA | D2: MACRO | E2: MASTER
A3: R3G | B3: CC | C3: PAGOMEN | D3: CREDICOOP | E3: MAESTRO
A4: R5G | B4: TDC | C4: PAGOCC | D4: SANTANDER | E4: AMEX
A5: R8G | B5: CLARO | D5: GALICIA | E5: NARANJA
A6: R15G | D6: HSBC | E6: CONSUMAX
A7: R25G | D7: NACION
D8: PBA
A9: MIG
A10: PROPIO
A11: ACCESORIO
A12: GASTO
A13: VARIO
A14: BAF
A15: P1G
A16: P3G
A17: P5G
A18: P8G
A19: P15G
A20: P25G
... A24: MAVERICK

Sheet CajaAcc
A1: FECHA | B1: DETALLE | C1: FAC. | D1: INGRESO | E1: Cant | F1: Código de barras | G1: DEST | H1: MODO | I1: Nº | J1: Movim. | K1: OBSERVACIONES | L1: M/m | M1: Costo sugerido | N1: Descripción
A2: 45200 | B2: Consumidor Final | D2: 3550 | E2: 1 | F2: 859184004010 | G2: tdc | H2: visa | J2: Lucila | L2: 5 | M2: =IFERROR(ROUNDUP(VLOOKUP(F2,Accesorio!A:E,IF(L2>5,L2-2,L2),)*E2/IF(L2>5,1.21,1),0)," ") -> 4200 | N2: =IFERROR(VLOOKUP(F2,Accesorio!A:C,3,),"") -> SOPORTE POP SOCKET DIS.
A3: 45200 | B3: Consumidor Final | D3: 5450 | E3: 1 | F3: SILFE22 | G3: caja | H3: efe | J3: Lucila | L3: 5 | M3: =IFERROR(ROUNDUP(VLOOKUP(F3,Accesorio!A:E,IF(L3>5,L3-2,L3),)*E3/IF(L3>5,1.21,1),0)," ") -> 6450 | N3: =IFERROR(VLOOKUP(F3,Accesorio!A:C,3,),"") -> TPU MOT. E22/E22i SILICONE FELPA
A4: 45201 | B4: Hug, Lucila | D4: 1288 | E4: 1 | F4: CMMTYPC | G4: caja | H4: efe | J4: Lucila | K4: Autoriza Mag | L4: 5 | M4: =IFERROR(ROUNDUP(VLOOKUP(F4,Accesorio!A:E,IF(L4>5,L4-2,L4),)*E4/IF(L4>5,1.21,1),0)," ") -> 4750 | N4: =IFERROR(VLOOKUP(F4,Accesorio!A:C,3,),"") -> CABLE TIPO C MAXICELL
A5: 45201 | B5: Consumidor Final | D5: 3700 | E5: 1 | F5: 4715000003698 | G5: tdc | H5: visa | J5: Lucas | L5: 5 | M5: =IFERROR(ROUNDUP(VLOOKUP(F5,Accesorio!A:E,IF(L5>5,L5-2,L5),)*E5/IF(L5>5,1.21,1),0)," ") -> 5100 | N5: =IFERROR(VLOOKUP(F5,Accesorio!A:C,3,),"") -> CAR. PARED TIPO C 2A
A6: 45201 | B6: Consumidor Final | D6: 30800 | E6: 1 | F6: PBS'QI10NE | G6: tdc | H6: visa | J6: Lucas | L6: 5 | M6: =IFERROR(ROUNDUP(VLOOKUP(F6,Accesorio!A:E,IF(L6>5,L6-2,L6),)*E6/IF(L6>5,1.21,1),0)," ") -> 36400 | N6: =IFERROR(VLOOKUP(F6,Accesorio!A:C,3,),"") -> POWER BANK + CAR. INALAMBRICO 10000 mAh SOUL DUAL USB NEGRO
A7: 45201 | B7: Consumidor Final | D7: 2650 | E7: 1 | F7: FD5D'A045NE | G7: tdc | H7: master | J7: Lucas | L7: 5 | M7: =IFERROR(ROUNDUP(VLOOKUP(F7,Accesorio!A:E,IF(L7>5,L7-2,L7),)*E7/IF(L7>5,1.21,1),0)," ") -> 3100 | N7: =IFERROR(VLOOKUP(F7,Accesorio!A:C,3,),"") -> GLASS FULL SAM. A04/A04S NEGRO 5D
A8: 45201 | B8: Consumidor Final | D8: 3150 | E8: 1 | F8: 413046 | G8: tdc | H8: visa | J8: Lucas | L8: 5 | M8: =IFERROR(ROUNDUP(VLOOKUP(F8,Accesorio!A:E,IF(L8>5,L8-2,L8),)*E8/IF(L8>5,1.21,1),0)," ") -> 3750 | N8: =IFERROR(VLOOKUP(F8,Accesorio!A:C,3,),"") -> TPU SAM. A04E SILICONE DIS. DK
A9: 45201 | B9: Acc Demo 3413257609 | D9: 1801 | E9: 1 | F9: HG'FILMS | G9: caja | H9: efe | J9: Lucila | K9: TCL405 | L9: 5 | M9: =IFERROR(ROUNDUP(VLOOKUP(F9,Accesorio!A:E,IF(L9>5,L9-2,L9),)*E9/IF(L9>5,1.21,1),0)," ") -> 3650 | N9: =IFERROR(VLOOKUP(F9,Accesorio!A:C,3,),"") -> HIDROGEL FILMINAS CLEAR 170X120
A10: 45201 | B10: Consumidor Final | D10: 3050 | E10: 1 | F10: 44199 | G10: tdc | H10: visa | J10: Lucila | L10: 5 | M10: =IFERROR(ROUNDUP(VLOOKUP(F10,Accesorio!A:E,IF(L10>5,L10-2,L10),)*E10/IF(L10>5,1.21,1),0)," ") -> 3600 | N10: =IFERROR(VLOOKUP(F10,Accesorio!A:C,3,),"") -> TPU SAM. A03 CORE PUFFER CASE
A11: 45201 | B11: Consumidor Final | D11: 3050 | E11: 1 | F11: 44200 | G11: tdc | H11: visa | J11: Lucila | L11: 5 | M11: =IFERROR(ROUNDUP(VLOOKUP(F11,Accesorio!A:E,IF(L11>5,L11-2,L11),)*E11/IF(L11>5,1.21,1),0)," ") -> 3600 | N11: =IFERROR(VLOOKUP(F11,Accesorio!A:C,3,),"") -> TPU SAM. A23 PUFFER CASE
A12: 45202 | B12: Campos, Ezequiel | D12: 9440 | E12: 1 | F12: 16729 | G12: caja | H12: efe | J12: Enzo | K12: Autoriza Mag | L12: 5 | M12: =IFERROR(ROUNDUP(VLOOKUP(F12,Accesorio!A:E,IF(L12>5,L12-2,L12),)*E12/IF(L12>5,1.21,1),0)," ") -> 21450 | N12: =IFERROR(VLOOKUP(F12,Accesorio!A:C,3,),"") -> AUR. BT BUD CAKE TWS 5.0
A13: 45202 | B13: Consumidor Final | D13: 4900 | E13: 1 | F13: RPUBRA24 | G13: caja | H13: efe | J13: Lucila | L13: 5 | M13: =IFERROR(ROUNDUP(VLOOKUP(F13,Accesorio!A:E,IF(L13>5,L13-2,L13),)*E13/IF(L13>5,1.21,1),0)," ") -> 5800 | N13: =IFERROR(VLOOKUP(F13,Accesorio!A:C,3,),"") -> TPU SAM. A24 BRILLOS
A14: 45202 | B14: Consumidor Final | D14: 2650 | E14: 1 | F14: FD5D'A145NE | G14: tdc | H14: visa | J14: Lucila | L14: 5 | M14: =IFERROR(ROUNDUP(VLOOKUP(F14,Accesorio!A:E,IF(L14>5,L14-2,L14),)*E14/IF(L14>5,1.21,1),0)," ") -> 3100 | N14: =IFERROR(VLOOKUP(F14,Accesorio!A:C,3,),"") -> GLASS FULL SAM. A14 NEGRO 5D
A15: 45202 | B15: Consumidor Final | D15: 3350 | E15: 1 | F15: HG'FILMS | G15: tdc | H15: visa | J15: Lucila | K15: G22 | L15: 5 | M15: =IFERROR(ROUNDUP(VLOOKUP(F15,Accesorio!A:E,IF(L15>5,L15-2,L15),)*E15/IF(L15>5,1.21,1),0)," ") -> 3650 | N15: =IFERROR(VLOOKUP(F15,Accesorio!A:C,3,),"") -> HIDROGEL FILMINAS CLEAR 170X120
A16: 45202 | B16: Consumidor Final | D16: 3700 | E16: 1 | F16: 4715000003698 | G16: tdc | H16: visa | J16: Enzo | L16: 5 | M16: =IFERROR(ROUNDUP(VLOOKUP(F16,Accesorio!A:E,IF(L16>5,L16-2,L16),)*E16/IF(L16>5,1.21,1),0)," ") -> 5100 | N16: =IFERROR(VLOOKUP(F16,Accesorio!A:C,3,),"") -> CAR. PARED TIPO C 2A
A17: 45203 | B17: Consumidor Final | D17: 7250 | E17: 1 | F17: 740617298680 | G17: caja | H17: efe | J17: Enzo | L17: 5 | M17: =IFERROR(ROUNDUP(VLOOKUP(F17,Accesorio!A:E,IF(L17>5,L17-2,L17),)*E17/IF(L17>5,1.21,1),0)," ") -> 8550 | N17: =IFERROR(VLOOKUP(F17,Accesorio!A:C,3,),"") -> MEMORIA MICROSD 32GB C10
A18: 45204 | B18: Consumidor Final | D18: 7250 | E18: 1 | F18: 619659184377 | G18: caja | H18: efe | J18: Lucila | L18: 5 | M18: =IFERROR(ROUNDUP(VLOOKUP(F18,Accesorio!A:E,IF(L18>5,L18-2,L18),)*E18/IF(L18>5,1.21,1),0)," ") -> 8550 | N18: =IFERROR(VLOOKUP(F18,Accesorio!A:C,3,),"") -> MEMORIA MICROSD 32GB C10
A19: 45204 | B19: Consumidor Final | D19: 3050 | E19: 1 | F19: 23414 | G19: caja | H19: efe | J19: Enzo | L19: 5 | M19: =IFERROR(ROUNDUP(VLOOKUP(F19,Accesorio!A:E,IF(L19>5,L19-2,L19),)*E19/IF(L19>5,1.21,1),0)," ") -> 3600 | N19: =IFERROR(VLOOKUP(F19,Accesorio!A:C,3,),"") -> TPU MOT. E13 PUFFER CASE
A20: 45204 | B20: Consumidor Final | D20: 2650 | E20: 1 | F20: FD5D'A042NE | G20: tdc | H20: visa | J20: Lucila | L20: 5 | M20: =IFERROR(ROUNDUP(VLOOKUP(F20,Accesorio!A:E,IF(L20>5,L20-2,L20),)*E20/IF(L20>5,1.21,1),0)," ") -> 3100 | N20: =IFERROR(VLOOKUP(F20,Accesorio!A:C,3,),"") -> GLASS FULL SAM. A04E NEGRO 5D
A21: 45204 | B21: Consumidor Final | D21: 3350 | E21: 1 | F21: HG'FILMS | G21: tdc | H21: visa | J21: Lucila | K21: Edge 30 Pro | L21: 5 | M21: =IFERROR(ROUNDUP(VLOOKUP(F21,Accesorio!A:E,IF(L21>5,L21-2,L21),)*E21/IF(L21>5,1.21,1),0)," ") -> 3650 | N21: =IFERROR(VLOOKUP(F21,Accesorio!A:C,3,),"") -> HIDROGEL FILMINAS CLEAR 170X120
A22: 45204 | B22: Consumidor Final | D22: 2650 | E22: 1 | F22: FD5D'A24 | G22: caja | H22: efe | J22: Enzo | L22: 5 | M22: =IFERROR(ROUNDUP(VLOOKUP(F22,Accesorio!A:E,IF(L22>5,L22-2,L22),)*E22/IF(L22>5,1.21,1),0)," ") -> 3100 | N22: =IFERROR(VLOOKUP(F22,Accesorio!A:C,3,),"") -> GLASS FULL SAM. A24 NEGRO 5D
A23: 45205 | B23: Consumidor Final | D23: 2050 | E23: 1 | F23: fdt'e13 | G23: caja | H23: efe | J23: Lucila | L23: 5 | M23: =IFERROR(ROUNDUP(VLOOKUP(F23,Accesorio!A:E,IF(L23>5,L23-2,L23),)*E23/IF(L23>5,1.21,1),0)," ") -> 2400 | N23: =IFERROR(VLOOKUP(F23,Accesorio!A:C,3,),"") -> GLASS MOT. E13
A24: 45205 | B24: Reposicion de acc | C24: 2198 | E24: -10 | F24: 4715000003698 | J24: Accesorios | M24: =IFERROR(ROUNDUP(VLOOKUP(F24,Accesorio!A:E,IF(L24>5,L24-2,L24),)*E24/IF(L24>5,1.21,1),0)," ") | N24: =IFERROR(VLOOKUP(F24,Accesorio!A:C,3,),"") -> CAR. PARED TIPO C 2A
A25: 45205 | B25: Reposicion de acc | C25: 2198 | E25: -5 | F25: 4715000003700 | J25: Accesorios | M25: =IFERROR(ROUNDUP(VLOOKUP(F25,Accesorio!A:E,IF(L25>5,L25-2,L25),)*E25/IF(L25>5,1.21,1),0)," ") | N25: =IFERROR(VLOOKUP(F25,Accesorio!A:C,3,),"") -> CAR. PARED MICRO 2A
A26: 45205 | B26: Reposicion de acc | C26: 2198 | E26: -2 | F26: 190199040670 | J26: Accesorios | M26: =IFERROR(ROUNDUP(VLOOKUP(F26,Accesorio!A:E,IF(L26>5,L26-2,L26),)*E26/IF(L26>5,1.21,1),0)," ") | N26: =IFERROR(VLOOKUP(F26,Accesorio!A:C,3,),"") -> CAR. PARED CABEZAL TIPO C - 20W 3A KOSMIC
A27: 45205 | B27: Reposicion de acc | C27: 2198 | E27: -2 | F27: SILFA14 | J27: Accesorios | M27: =IFERROR(ROUNDUP(VLOOKUP(F27,Accesorio!A:E,IF(L27>5,L27-2,L27),)*E27/IF(L27>5,1.21,1),0)," ") | N27: =IFERROR(VLOOKUP(F27,Accesorio!A:C,3,),"") -> TPU SAM. A14 SILICONE FELPA
A28: 45205 | B28: Reposicion de acc | C28: 2198 | E28: -3 | F28: SILFE22 | J28: Accesorios | M28: =IFERROR(ROUNDUP(VLOOKUP(F28,Accesorio!A:E,IF(L28>5,L28-2,L28),)*E28/IF(L28>5,1.21,1),0)," ") | N28: =IFERROR(VLOOKUP(F28,Accesorio!A:C,3,),"") -> TPU MOT. E22/E22i SILICONE FELPA
A29: 45205 | B29: Reposicion de acc | C29: 2198 | E29: -2 | F29: SILFG72 | J29: Accesorios | M29: =IFERROR(ROUNDUP(VLOOKUP(F29,Accesorio!A:E,IF(L29>5,L29-2,L29),)*E29/IF(L29>5,1.21,1),0)," ") | N29: =IFERROR(VLOOKUP(F29,Accesorio!A:C,3,),"") -> TPU MOT. G72 SILICONE FELPA
A30: 45205 | B30: Reposicion de acc | C30: 2198 | E30: -1 | F30: SILFIPH11 | J30: Accesorios | M30: =IFERROR(ROUNDUP(VLOOKUP(F30,Accesorio!A:E,IF(L30>5,L30-2,L30),)*E30/IF(L30>5,1.21,1),0)," ") | N30: =IFERROR(VLOOKUP(F30,Accesorio!A:C,3,),"") -> TPU IPH 11 /XR SILICONE FELPA
A31: 45205 | B31: Reposicion de acc | C31: 2198 | E31: -1 | F31: SILFA24 | J31: Accesorios | M31: =IFERROR(ROUNDUP(VLOOKUP(F31,Accesorio!A:E,IF(L31>5,L31-2,L31),)*E31/IF(L31>5,1.21,1),0)," ") | N31: =IFERROR(VLOOKUP(F31,Accesorio!A:C,3,),"") -> TPU SAM. A24 SILICONE FELPA
A32: 45205 | B32: Reposicion de acc | C32: 2198 | E32: -1 | F32: SILFG32 | J32: Accesorios | M32: =IFERROR(ROUNDUP(VLOOKUP(F32,Accesorio!A:E,IF(L32>5,L32-2,L32),)*E32/IF(L32>5,1.21,1),0)," ") | N32: =IFERROR(VLOOKUP(F32,Accesorio!A:C,3,),"") -> TPU MOT. G32 SILICONE FELPA
A33: 45205 | B33: Reposicion de acc | C33: 2198 | E33: -1 | F33: SILFG22 | J33: Accesorios | M33: =IFERROR(ROUNDUP(VLOOKUP(F33,Accesorio!A:E,IF(L33>5,L33-2,L33),)*E33/IF(L33>5,1.21,1),0)," ") | N33: =IFERROR(VLOOKUP(F33,Accesorio!A:C,3,),"") -> TPU MOT. G22/E32 SILICONE FELPA
A34: 45205 | B34: Reposicion de acc | C34: 2198 | E34: -1 | F34: TRRSA24 | J34: Accesorios | M34: =IFERROR(ROUNDUP(VLOOKUP(F34,Accesorio!A:E,IF(L34>5,L34-2,L34),)*E34/IF(L34>5,1.21,1),0)," ") | N34: =IFERROR(VLOOKUP(F34,Accesorio!A:C,3,),"") -> TPU SAM. A24 RUBBER
A35: 45205 | B35: Reposicion de acc | C35: 2198 | E35: -1 | F35: FPSA34 | J35: Accesorios | M35: =IFERROR(ROUNDUP(VLOOKUP(F35,Accesorio!A:E,IF(L35>5,L35-2,L35),)*E35/IF(L35>5,1.21,1),0)," ") | N35: =IFERROR(VLOOKUP(F35,Accesorio!A:C,3,),"") -> TPU SAM. A34 PUFFER IMP.
... A57: 45205 | B57: Reposicion de acc | C57: 2198 | E57: -1 | F57: CMMIPH | J57: Accesorios | M57: =IFERROR(ROUNDUP(VLOOKUP(F57,Accesorio!A:E,IF(L57>5,L57-2,L57),)*E57/IF(L57>5,1.21,1),0)," ") | N57: =IFERROR(VLOOKUP(F57,Accesorio!A:C,3,),"") -> CABLE LIGHTNING IPH 7 1MTS MAXICELL
A58: 45206 | B58: Consumidor Final | D58: 17550 | E58: 1 | F58: 14FMTUR3A | G58: tdc | H58: visa | J58: Lucas | L58: 5 | M58: =IFERROR(ROUNDUP(VLOOKUP(F58,Accesorio!A:E,IF(L58>5,L58-2,L58),)*E58/IF(L58>5,1.21,1),0)," ") -> 20750 | N58: =IFERROR(VLOOKUP(F58,Accesorio!A:C,3,),"") -> CAR. AUTO MICRO TURBO 3A MOT. OR.
A59: 45206 | B59: Consumidor Final | D59: 2250 | E59: 1 | F59: FDT'A346 | G59: caja | H59: efe | J59: Enzo | L59: 5 | M59: =IFERROR(ROUNDUP(VLOOKUP(F59,Accesorio!A:E,IF(L59>5,L59-2,L59),)*E59/IF(L59>5,1.21,1),0)," ") -> 2650 | N59: =IFERROR(VLOOKUP(F59,Accesorio!A:C,3,),"") -> GLASS SAM. A34
A60: 45206 | B60: Consumidor Final | D60: 5050 | E60: 1 | F60: FPSA14 | G60: caja | H60: efe | J60: Lucas | L60: 5 | M60: =IFERROR(ROUNDUP(VLOOKUP(F60,Accesorio!A:E,IF(L60>5,L60-2,L60),)*E60/IF(L60>5,1.21,1),0)," ") -> 5950 | N60: =IFERROR(VLOOKUP(F60,Accesorio!A:C,3,),"") -> TPU SAM. A14 PUFFER IMP.
A61: 45206 | B61: Consumidor Final | D61: 3050 | E61: 1 | F61: 22522 | G61: caja | H61: efe | J61: Lucas | L61: 5 | M61: =IFERROR(ROUNDUP(VLOOKUP(F61,Accesorio!A:E,IF(L61>5,L61-2,L61),)*E61/IF(L61>5,1.21,1),0)," ") -> 3600 | N61: =IFERROR(VLOOKUP(F61,Accesorio!A:C,3,),"") -> TPU MOT. E22/E22i PUFFER CASE
...

Sheet Accesorio
A1: CodigoCeiba | B1: Categorias | C1: Descripción | D1: PrecioMayorista | E1: PrecioPúblico | F1: Actual | G1: Inicial | H1: =IF(SUM(CajaAcc!E:E)+SUM(F:F)-SUM(G:G)=0,"BIEN","HAY ERRORES") -> BIEN
A2: 17078 | B2: AURICULAR | C2: AUR. BT BUD A6S MiPods 5.0 | D2: 8653 | E2: 16650 | F2: =-SUMIF(CajaAcc!F:F,A2,CajaAcc!E:E)+G2 -> 2 | G2: 2
A3: 16729 | B3: AURICULAR | C3: AUR. BT BUD CAKE TWS 5.0 | D3: 11162 | E3: 21450 | F3: =-SUMIF(CajaAcc!F:F,A3,CajaAcc!E:E)+G3 -> 0 | G3: 1
A4: 17080 | B4: AURICULAR | C4: AUR. BT BUD F9 5.0 | D4: 11865 | E4: 22800 | F4: =-SUMIF(CajaAcc!F:F,A4,CajaAcc!E:E)+G4 -> 0 | G4: 0
A5: I12STWS | B5: AURICULAR | C5: AUR. BT BUD I12S TWS 5.0 | D5: 7441 | E5: 14300 | F5: =-SUMIF(CajaAcc!F:F,A5,CajaAcc!E:E)+G5 -> 1 | G5: 2
A6: 16994 | B6: AURICULAR | C6: AUR. BT BUD I13 TWS 5.0 | D6: 9653 | E6: 18550 | F6: =-SUMIF(CajaAcc!F:F,A6,CajaAcc!E:E)+G6 -> 0 | G6: 0
A7: L21TWS | B7: AURICULAR | C7: AUR. BT BUD L21 TWS 5.0 | D7: 9151 | E7: 17600 | F7: =-SUMIF(CajaAcc!F:F,A7,CajaAcc!E:E)+G7 -> 0 | G7: 0
A8: 8806092507265 | B8: AURICULAR | C8: AUR. BT BUD SAM. BUDS 2 sm-r177nzk | D8: 64586 | E8: 89450 | F8: =-SUMIF(CajaAcc!F:F,A8,CajaAcc!E:E)+G8 -> 2 | G8: 2
A9: 8806090517037 | B9: AURICULAR | C9: AUR. BT BUD SAM. BUDS Live sm-r180nzk | D9: 64586 | E9: 89450 | F9: =-SUMIF(CajaAcc!F:F,A9,CajaAcc!E:E)+G9 -> 0 | G9: 1
A10: 7798081286880 | B10: AURICULAR | C10: AUR. BT BUD SMARTLIFE GAMER SL-EBG207B NEGRO | D10: 25325 | E10: 38950 | F10: =-SUMIF(CajaAcc!F:F,A10,CajaAcc!E:E)+G10 -> 0 | G10: 0
A11: 7798081286897 | B11: AURICULAR | C11: AUR. BT BUD SMARTLIFE GAMER SL-EBG207G GRIS | D11: 25325 | E11: 38950 | F11: =-SUMIF(CajaAcc!F:F,A11,CajaAcc!E:E)+G11 -> 0 | G11: 0
A12: 7798081286866 | B12: AURICULAR | C12: AUR. BT BUD SMARTLIFE SL-EBP201B NEGRO | D12: 31381 | E12: 48300 | F12: =-SUMIF(CajaAcc!F:F,A12,CajaAcc!E:E)+G12 -> 0 | G12: 0
A13: 7798081286873 | B13: AURICULAR | C13: AUR. BT BUD SMARTLIFE SL-EBP201W BANCO | D13: 31381 | E13: 48300 | F13: =-SUMIF(CajaAcc!F:F,A13,CajaAcc!E:E)+G13 -> 0 | G13: 0
... A2804: TPURSA51 | B2804: TPU | C2804: TPU SAM. A51 REF SOFT | D2804: 759 | E2804: 2050 | F2804: =-SUMIF(CajaAcc!F:F,A2804,CajaAcc!E:E)+G2804 -> 0 | G2804: 0
A2805: TPURS'A515NE | B2805: TPU | C2805: TPU SAM. A51 REF SOFT | D2805: 759 | E2805: 2050 | F2805: =-SUMIF(CajaAcc!F:F,A2805,CajaAcc!E:E)+G2805 -> 0 | G2805: 0 | H2805: 15600
A2806: TRRSA51 | B2806: TPU | C2806: TPU SAM. A51 RUBBER | D2806: 2180 | E2806: 5850 | F2806: =-SUMIF(CajaAcc!F:F,A2806,CajaAcc!E:E)+G2806 -> 0 | G2806: 0
A2807: TTXSA51 | B2807: TPU | C2807: TPU SAM. A51 TEXTURADO | D2807: 975 | E2807: 2250 | F2807: =-SUMIF(CajaAcc!F:F,A2807,CajaAcc!E:E)+G2807 -> 0 | G2807: 0
A2808: TPUSA51TD | B2808: TPU | C2808: TPU SAM. A51 TRANS DIS. | D2808: 716 | E2808: 1650 | F2808: =-SUMIF(CajaAcc!F:F,A2808,CajaAcc!E:E)+G2808 -> 0 | G2808: 0
A2809: TDNSA52 | B2809: TPU | C2809: TPU SAM. A52 / A52S DIS. NAC. | D2809: 960 | E2809: 2600 | F2809: =-SUMIF(CajaAcc!F:F,A2809,CajaAcc!E:E)+G2809 -> 1 | G2809: 1
A2810: TPURS'A526AZ | B2810: TPU | C2810: TPU SAM. A52 / A52S REF SOFT | D2810: 1376 | E2810: 3700 | F2810: =-SUMIF(CajaAcc!F:F,A2810,CajaAcc!E:E)+G2810 -> 0 | G2810: 0
A2811: TPURS'A526FU | B2811: TPU | C2811: TPU SAM. A52 / A52S REF SOFT | D2811: 1376 | E2811: 3700 | F2811: =-SUMIF(CajaAcc!F:F,A2811,CajaAcc!E:E)+G2811 -> 0 | G2811: 0
A2812: TPURS'A526NE | B2812: TPU | C2812: TPU SAM. A52 / A52S REF SOFT | D2812: 1376 | E2812: 3700 | F2812: =-SUMIF(CajaAcc!F:F,A2812,CajaAcc!E:E)+G2812 -> 0 | G2812: 0
A2813: TRRSA52 | B2813: TPU | C2813: TPU SAM. A52 / A52S RUBBER | D2813: 2180 | E2813: 5850 | F2813: =-SUMIF(CajaAcc!F:F,A2813,CajaAcc!E:E)+G2813 -> 1 | G2813: 1
A2814: 33341 | B2814: TPU | C2814: TPU SAM. A52 / A52S SILICONE | D2814: 955 | E2814: 2950 | F2814: =-SUMIF(CajaAcc!F:F,A2814,CajaAcc!E:E)+G2814 -> 8 | G2814: 8
A2815: 4564568286971 | B2815: TPU | C2815: TPU SAM. A52 / A52S SILICONE C/MARCA | D2815: 3160 | E2815: 9700 | F2815: =-SUMIF(CajaAcc!F:F,A2815,CajaAcc!E:E)+G2815 -> 1 | G2815: 1
A2816: 1681 | B2816: TPU | C2816: TPU SAM. A52 / A52S SILICONE DIS. DK | D2816: 1106 | E2816: 3750 | F2816: =-SUMIF(CajaAcc!F:F,A2816,CajaAcc!E:E)+G2816 -> 0 | G2816: 0
A2817: 1780 | B2817: TPU | C2817: TPU SAM. A52 / A52S SILICONE DIS. DK | D2817: 1106 | E2817: 3750 | F2817: =-SUMIF(CajaAcc!F:F,A2817,CajaAcc!E:E)+G2817 -> 0 | G2817: 0
... A3211: FDT'MED30N | B3211: GLASS | C3211: GLASS MOT. EDGE 30 NEO | D3211: 507 | E3211: 2150 | F3211: =-SUMIF(CajaAcc!F:F,A3211,CajaAcc!E:E)+G3211 -> 1 | G3211: 0

Sheet TablaPuntos
A1: ACCESORIO | B1: PROPIO | C1: PREPAGA | D1: BAF | E1: R1G | F1: R3G | G1: R5G | H1: R8G | I1: R15G | J1: R25G | K1: P280 | L1: P1G | M1: P3G | N1: P5G | O1: P8G | P1: P15G | Q1: P25G | R1: Cater | T1: OBJETIVO
A2: 70 | B2: 150 | C2: 1000 | D2: 230 | E2: 33 | F2: 38 | G2: 43 | H2: 55 | I2: 85 | J2: 110 | K2: 0 | L2: 50 | M2: 63 | N2: 78 | O2: 100 | P2: 160 | Q2: 220 | R2: 33 | T2: Accesorio | U2: Puntos
A3: D | B3: D | C3: D | T3: 701316 | U3: 20112

Sheet Objetivos
A1: OBJETIVOS
A2: ACCESORIO | B2: PROPIO | C2: PREPAGA | D2: BAF | E2: R1G | F2: R3G | G2: R5G | H2: R8G | I2: R15G | J2: R25G | K2: P280 | L2: P1G | M2: P3G | N2: P5G | O2: P8G | P2: P15G | Q2: P25G | R2: Cater | S2: Puntos logrados | T2: Puntos Objetivos | U2: Duplica | V2: %Logrado
A3: =IF(TablaPuntos!A3 = "D",A7/TablaPuntos!A2,A7*TablaPuntos!A2)+IF(TablaPuntos!T3>0,IF(Objetivos!A7>TablaPuntos!T3,TablaPuntos!T3/TablaPuntos!A2,0),0) -> 22292.171 | B3: =IF(TablaPuntos!B3 = "D",B7/TablaPuntos!B2,B7*TablaPuntos!B2) -> 3027.8667 | C3: =IF(TablaPuntos!C3 = "D",C7/TablaPuntos!C2,C7*TablaPuntos!C2) -> 74.99899 | D3: =IF(TablaPuntos!D3 = "D",D7/TablaPuntos!D2,D7*TablaPuntos!D2) -> 3220 | E3: =IF(TablaPuntos!E3 = "D",E7/TablaPuntos!E2,E7*TablaPuntos!E2) -> 66 | F3: =IF(TablaPuntos!F3 = "D",F7/TablaPuntos!F2,F7*TablaPuntos!F2) -> 342 | G3: =IF(TablaPuntos!G3 = "D",G7/TablaPuntos!G2,G7*TablaPuntos!G2) -> 86 | H3: =IF(TablaPuntos!H3 = "D",H7/TablaPuntos!H2,H7*TablaPuntos!H2) -> 55 | I3: =IF(TablaPuntos!I3 = "D",I7/TablaPuntos!I2,I7*TablaPuntos!I2) -> 85 | ... R3: =IF(TablaPuntos!R3 = "D",R7/TablaPuntos!R2,R7*TablaPuntos!R2) -> 924 | S3: =SUM(A3:R3) -> 30774.037 | T3: =TablaPuntos!U3 -> 20112 | U3: =IF(TablaPuntos!T3>0,IF(A7>TablaPuntos!T3,"DUPLICA","NO DUPLICA"),"NO DUPLICA") -> DUPLICA | V3: =S3/T3 -> 1.5301331
A5: INGRESOS
A6: ACCESORIO | B6: PROPIO | C6: PREPAGA | D6: BAF | E6: R1G | F6: R3G | G6: R5G | H6: R8G | I6: R15G | J6: R25G | K6: P280 | L6: P1G | M6: P3G | N6: P5G | O6: P8G | P6: P15G | Q6: P25G | R6: Cater
A7: =SUMIF(CAJA!$G:$G,A6,CAJA!$D:$D) -> 859136 | B7: =SUMIF(CAJA!$G:$G,B6,CAJA!$D:$D)-SUMIF(CAJA!$H:$H,"SIM*",CAJA!$D:$D) -> 454180.01 | C7: =SUMIF(CAJA!$G:$G,C6,CAJA!$D:$D) -> 74998.99 | D7: =SUMIF(CAJA!$G:$G,D6,CAJA!$F:$F) -> 14 | E7: =SUMIF(CAJA!$G:$G,E6,CAJA!$F:$F) -> 2 | F7: =SUMIF(CAJA!$G:$G,F6,CAJA!$F:$F) -> 9 | G7: =SUMIF(CAJA!$G:$G,G6,CAJA!$F:$F) -> 2 | H7: =SUMIF(CAJA!$G:$G,H6,CAJA!$F:$F) -> 1 | I7: =SUMIF(CAJA!$G:$G,I6,CAJA!$F:$F) -> 1 | J7: =SUMIF(CAJA!$G:$G,J6,CAJA!$F:$F) -> 0 | K7: =SUMIF(CAJA!$G:$G,K6,CAJA!$F:$F) -> 0 | ... R7: =SUMIF(CAJA!$G:$G,R6,CAJA!$F:$F) -> 28
